Generating pipelines...
2 pipelines have been generated.

Pipeline1: Clustering the samples.
[11:52AM] 1.convert_signal_to_tdf
[11:52AM] 2.log_signal
[11:52AM] 3.fill_missing_with_zeros
[11:53AM] 4.convert_signal_to_pcl
[11:53AM] 5.cluster_genes_by_kmeans
[11:53AM] 6.annotate_probe
[12:03PM] Completed successfully and generated a file:
/home/xchen/chencode/examples/sample_analysis/annotate_probe_BETSYHASH1_da311fc262908b35eee1bc60a5e7b7de/cluster_file_annot_path.975135a11a7013ff.6272656173745f31392e6d617335.txt

Pipeline2: Plotting a heatmap of the samples.
[12:03PM] 1.convert_signal_to_tdf
[12:03PM] 2.log_signal
[12:03PM] 3.fill_missing_with_zeros
[12:03PM] 4.convert_signal_to_pcl
[12:03PM] 5.cluster_genes_by_kmeans
[12:03PM] 6.plot_signal_heatmap
Traceback (most recent call last):
  File "/home/xchen/chencode/Betsy/scripts/run_protocol.py", line 211, in <module>
    main()
  File "/home/xchen/chencode/Betsy/scripts/run_protocol.py", line 200, in main
    parameters,clean_up=args.clean_up)
  File "/home/xchen/chencode/Betsy/scripts/run_protocol.py", line 76, in run_protocol
    out_files = rule_engine.run_pipeline(pipeline, objects,clean_up=clean_up)
  File "/home/xchen/chencode/Betsy/Betsy/rule_engine.py", line 224, in run_pipeline
    analysis,objects,pipeline_sequence,clean_up=clean_up)
  File "/home/xchen/chencode/Betsy/Betsy/rule_engine.py", line 169, in run_module
    analysis.parameters, objects, pipeline_sequence)
  File "/home/xchen/chencode/Betsy/Betsy/modules/plot_signal_heatmap.py", line 29, in run
    raise ValueError(error_message)
ValueError: Traceback (most recent call last):
  File "/home/xchen/chencode/scripts/arrayplot.py", line 2279, in <module>
    main()
  File "/home/xchen/chencode/scripts/arrayplot.py", line 2271, in main
    options.width, options.height)
AssertionError: 388x1093508 plot too big [20:20].

